Workbook

Sheet Resultados
A1: Semana/Fecha | B1: Reportado por | C1: Resultado | D1: Equipo Ganador | E1: Equipo Perdedor | F1: Jugador | G1: Equipo | H1: Resultado Jugador | I1: Week | J1: Pokemon 1 | K1: Pokemon 2 | L1: Pokemon 3 | M1: Pokemon 4 | N1: Pokemon 5 | O1: Pokemon 6
A2: 08/05/2026 | B2: WiWivgc | C2: Win Izi peruanos 2-0 BZE | D2: Izi peruanos | E2: BZE | F2: William Chochoca | G2: Izi peruanos | H2: 2 | I2: 2 | J2: Aerodactyl | K2: kommo | L2: Kingambit | M2: Scovillan mega | N2: Sneasler | O2: Basculegion-Male
A3: 08/05/2026 | B3: WiWivgc | C3: Win Izi peruanos 2-0 BZE | D3: Izi peruanos | E3: BZE | F3: Manuel Espiritu | G3: BZE | H3: 0 | I3: 2 | J3: Arcanine | K3: Gardevoir Mega | L3: Tyranitar | M3: rotom_wash | N3: Garchomp | O3: Corviknight
A4: 08/05/2026 | B4: Gcerbat33 | C4: Win BZE 2-0 Izi peruanos | D4: BZE | E4: Izi peruanos | F4: Sergio Aguirre | G4: BZE | H4: 2 | I4: 2 | J4: Kangaskhan Mega | K4: Farigiraf | L4: Basculegion-Male | M4: Torkoal | N4: Kingambit | O4: Sylveon
A5: 08/05/2026 | B5: Gcerbat33 | C5: Win BZE 2-0 Izi peruanos | D5: BZE | E5: Izi peruanos | F5: Bryan Changa | G5: Izi peruanos | H5: 0 | I5: 2 | J5: Charizard_Mega_Y | K5: Floette-Eternal | L5: Aerodactyl | M5: Garchomp | N5: Kingambit | O5: Basculegion-Male
A6: 09/05/2026 | B6: Cogao | C6: MtDrumr 2-0 Daishiro (no show) | D6: MtDrumr | E6: Daishiro | F6: MtDrumr | G6: MtDrumr | H6: 2 | I6: 2
A7: 09/05/2026 | B7: Cogao | C7: MtDrumr 2-0 Daishiro (no show) | D7: MtDrumr | E7: Daishiro | F7: Daishiro | G7: Daishiro | H7: 0 | I7: 2
A8: 09/05/2026 | B8: Yuanyo | C8: Win FBZ 2-0 TyM | D8: FBZ | E8: TyM | F8: Gabriel | G8: FBZ | H8: 2 | I8: 2 | J8: Venusaur Mega | K8: Archaludon | L8: Pelipper | M8: Basculegion-Male | N8: Sableye | O8: Kingambit
A9: 09/05/2026 | B9: Yuanyo | C9: Win FBZ 2-0 TyM | D9: FBZ | E9: TyM | F9: Jesus Pinto | G9: TyM | H9: 0 | I9: 2 | J9: Aerodactyl Mega | K9: Scovillan mega | L9: kommo | M9: Sneasler | N9: Kingambit | O9: Sylveon
A10: 09/05/2026 | B10: Rainer.M | C10: Win FakeoutSD 2-0 WishbornDragons | D10: FakeoutSD | E10: WishbornDragons | F10: Rainer | G10: FakeoutSD | H10: 2 | I10: 2 | J10: Pelipper | K10: Basculegion-Male | L10: Dragonite | M10: Kingambit | N10: Sneasler | O10: Archaludon
A11: 09/05/2026 | B11: Rainer.M | C11: Win FakeoutSD 2-0 WishbornDragons | D11: FakeoutSD | E11: WishbornDragons | F11: Gyisus | G11: WishbornDragons | H11: 0 | I11: 2 | J11: Venusaur | K11: Scizor | L11: Pelipper | M11: Basculegion-Male | N11: Archaludon | O11: Incineroar
A12: 09/05/2026 | B12: SChonso17 | C12: Win FakeoutSD 2-1 WishbornDragons | D12: FakeoutSD | E12: WishbornDragons | F12: Luis Alonso Coello | G12: FakeoutSD | H12: 2 | I12: 2 | J12: Gardevoir Mega | K12: Garchomp | L12: Talonflame | M12: Basculegion-Male | N12: Kingambit | O12: maushold_family_of_four
A13: 09/05/2026 | B13: SChonso17 | C13: Win FakeoutSD 2-1 WishbornDragons | D13: FakeoutSD | E13: WishbornDragons | F13: Rodrigo Rodriguez Ruelas | G13: WishbornDragons | H13: 1 | I13: 2 | J13: Incineroar | K13: Farigiraf | L13: Charizard_Mega_Y | M13: Drampa | N13: Torkoal | O13: Hatterene
A14: 09/05/2026 | B14: sabergio15 | C14: Win BZE 2-0 IZP | D14: BZE | E14: IZP | F14: Giorgio Falconi | G14: BZE | H14: 2 | I14: 2 | J14: Talonflame | K14: Garchomp | L14: Sneasler | M14: Basculegion-Male | N14: Kingambit | O14: Floette-Eternal
A15: 09/05/2026 | B15: sabergio15 | C15: Win BZE 2-0 IZP | D15: BZE | E15: IZP | F15: Gonzalo Padilla | G15: IZP | H15: 0 | I15: 2 | J15: Gardevoir Mega | K15: Sneasler | L15: Pelipper | M15: Incineroar | N15: Basculegion-Male | O15: Kingambit
A16: 09/05/2026 | B16: Val | C16: Win T&M 2-1 FBZ | D16: T&M | E16: FBZ | F16: Italo | G16: T&M | H16: 2 | I16: 2 | J16: Whimsicott | K16: Venusaur Mega | L16: Charizard_Mega_Y | M16: Garchomp | N16: Basculegion-Male | O16: Kingambit
A17: 09/05/2026 | B17: Val | C17: Win T&M 2-1 FBZ | D17: T&M | E17: FBZ | F17: Juanjo | G17: FBZ | H17: 1 | I17: 2 | J17: Aerodactyl Mega | K17: Scovillan mega | L17: Sneasler | M17: Basculegion-Male | N17: Kingambit | O17: kommo
A18: 10/05/2026 | B18: severed_ashe | C18: BZE No Show vs IZP | D18: IZP | E18: BZE | F18: Sam IZP | G18: IZP | H18: 2 | I18: 2
A19: 10/05/2026 | B19: severed_ashe | C19: BZE No Show vs IZP | D19: IZP | E19: BZE | F19: Israel BZE | G19: BZE | H19: 0 | I19: 2
A20: 10/05/2026 | B20: RenzoNavarro | C20: Win FakeoutSD 2-0 WishbornDragons | D20: FakeoutSD | E20: WishbornDragons | F20: Renzo | G20: FakeoutSD | H20: 2 | I20: 2 | J20: Floette-Eternal | K20: Aerodactyl | L20: Sneasler | M20: Incineroar | N20: Garchomp | O20: Basculegion-Male
A21: 10/05/2026 | B21: RenzoNavarro | C21: Win FakeoutSD 2-0 WishbornDragons | D21: FakeoutSD | E21: WishbornDragons | F21: Jr | G21: WishbornDragons | H21: 0 | I21: 2 | J21: Gengar mega | K21: rotom_wash | L21: Aegislash blade | M21: ninetales_alola | N21: Garchomp | O21: Incineroar
A22: 10/05/2026 | B22: Mesquo14 | C22: Win BZE 2-1 IZP | D22: BZE | E22: IZP | F22: Hanns | G22: BZE | H22: 2 | I22: 2 | J22: Kangaskhan Mega | K22: Torkoal | L22: Farigiraf | M22: Hatterene | N22: Kingambit | O22: Venusaur
A23: 10/05/2026 | B23: Mesquo14 | C23: Win BZE 2-1 IZP | D23: BZE | E23: IZP | F23: Jesus | G23: IZP | H23: 1 | I23: 2 | J23: Charizard_Mega_Y | K23: Froslass Mega | L23: Aerodactyl | M23: Basculegion-Male | N23: Kingambit | O23: Dragonite
A24: 10/05/2026 | B24: Itzer | C24: Win SS 2-0 PSG | D24: SS | E24: PSG | F24: Cristian Palante | G24: SS | H24: 2 | I24: 2 | J24: Charizard_Mega_Y | K24: Kingambit | L24: Sneasler | M24: Garchomp | N24: Basculegion-Male | O24: Whimsicott
A25: 10/05/2026 | B25: Itzer | C25: Win SS 2-0 PSG | D25: SS | E25: PSG | F25: André Távara | G25: PSG | H25: 0 | I25: 2 | J25: Kingambit | K25: ninetales_alola | L25: Gengar mega | M25: Dragonite | N25: Incineroar | O25: Sneasler
A26: 10/05/2026 | B26: Cob25 | C26: Win T&M 2-0 FBZ | D26: T&M | E26: FBZ | F26: Juan Silva (A25) | G26: T&M | H26: 2 | I26: 2 | J26: Kangaskhan mega | K26: Farigiraf | L26: Torkoal | M26: Basculegion-Male | N26: Kingambit | O26: Sylveon
A27: 10/05/2026 | B27: Cob25 | C27: Win T&M 2-0 FBZ | D27: T&M | E27: FBZ | F27: Luis Allasi (Pokelucho) | G27: FBZ | H27: 0 | I27: 2 | J27: ninetales_alola | K27: Sneasler | L27: Gengar mega | M27: Kingambit | N27: Incineroar | O27: Dragonite
A28: 10/05/2026 | B28: Sebastian Solari | C28: Win SS 2-0 PSG (No show) | D28: SS | E28: PSG | F28: Alfonso Huillcaya | G28: SS | H28: 2 | I28: 2
A29: 10/05/2026 | B29: Sebastian Solari | C29: Win SS 2-0 PSG (No show) | D29: SS | E29: PSG | F29: Pablo Verástegui | G29: PSG | H29: 0 | I29: 2
A30: 10/05/2026 | B30: Val | C30: Win T&M 2-1 FBZ | D30: T&M | E30: FBZ | F30: Roberto Pozo | G30: T&M | H30: 2 | I30: 2 | J30: Farigiraf | K30: Torkoal | L30: Sylveon | M30: Kingambit | N30: Basculegion-Male | O30: Kangaskhan Mega
A31: 10/05/2026 | B31: Val | C31: Win T&M 2-1 FBZ | D31: T&M | E31: FBZ | F31: Benjamin Ruiz | G31: FBZ | H31: 1 | I31: 2 | J31: Charizard_Mega_Y | K31: Sneasler | L31: Basculegion-Male | M31: Incineroar | N31: Venusaur | O31: Garchomp
A32: 11/05/2026 | B32: WhoIsSkrollex | C32: Win SS 2-1 PSG | D32: SS | E32: PSG | F32: Ernesto Serpa | G32: SS | H32: 2 | I32: 2 | J32: Floette-Eternal | K32: Incineroar | L32: Camerupt mega | M32: Sinitscha | N32: maushold_family_of_four | O32: mimikyu-disguised
A33: 11/05/2026 | B33: WhoIsSkrollex | C33: Win SS 2-1 PSG | D33: SS | E33: PSG | F33: Carlos Verastegui | G33: PSG | H33: 1 | I33: 2 | J33: Charizard_Mega_Y | K33: Floette-Eternal | L33: Kingambit | M33: Basculegion-Male | N33: Aerodactyl | O33: Garchomp
A34: 11/05/2026 | B34: Limonfito | C34: Win WSH 2-0 FakeOutSD | D34: WSH | E34: FakeOutSD | F34: Fito Pezán | G34: WSH | H34: 2 | I34: 2 | J34: Aerodactyl | K34: Floette-Eternal | L34: Garchomp | M34: Basculegion-Male | N34: Sneasler | O34: Kingambit
A35: 11/05/2026 | B35: Limonfito | C35: Win WSH 2-0 FakeOutSD | D35: WSH | E35: FakeOutSD | F35: Héctor Acuña | G35: FakeOutSD | H35: 0 | I35: 2 | J35: Charizard_Mega_Y | K35: Farigiraf | L35: Aerodactyl | M35: Sylveon | N35: Basculegion-Male | O35: Garchomp
A36: 11/05/2026 | B36: Rod | C36: Win SS 2-0 PSG | D36: SS | E36: PSG | F36: Rodrigo Montoya | G36: SS | H36: 2 | I36: 2 | J36: Tyranitar | K36: Excadrill | L36: Sneasler | M36: Scovillan mega | N36: Corviknight | O36: Basculegion-Male
A37: 11/05/2026 | B37: Rod | C37: Win SS 2-0 PSG | D37: SS | E37: PSG | F37: Bryan More | G37: PSG | H37: 0 | I37: 2 | J37: Tyranitar | K37: Excadrill | L37: Sneasler | M37: Incineroar | N37: Basculegion-Male | O37: Dragonite
A38: 11/05/2026 | B38: Sebastian Solari | C38: Win SS 2-0 PSG | D38: SS | E38: PSG | F38: Sebastian Solari | G38: SS | H38: 2 | I38: 2 | J38: Charizard_Mega_Y | K38: Aerodactyl | L38: Kingambit | M38: Floette-Eternal | N38: Garchomp | O38: Basculegion-Male
A39: 11/05/2026 | B39: Sebastian Solari | C39: Win SS 2-0 PSG | D39: SS | E39: PSG | F39: Glauco Valdivieso | G39: PSG | H39: 0 | I39: 2 | J39: Blastoise | K39: Pelipper | L39: Primarina | M39: Starmie | N39: Archaludon | O39: Basculegion-Male
A40: 11/05/2026 | B40: GonzAL-TH | C40: Win FSD 2-1 WSH | D40: FSD | E40: WSH | F40: Gonzalo Barrera | G40: FSD | H40: 2 | I40: 2 | J40: Kingambit | K40: Aerodactyl Mega | L40: Scovillan mega | M40: Sneasler | N40: Basculegion-Male | O40: kommo
...

Sheet Pokémon Usage
A1: Pokémon | B1: Veces Usado
A2: Basculegion-Male | B2: 54
A3: Kingambit | B3: 48
A4: Garchomp | B4: 36
A5: Sneasler | B5: 32
A6: Incineroar | B6: 27
A7: Aerodactyl | B7: 17
A8: Sylveon | B8: 14
A9: Floette-Eternal | B9: 14
A10: Farigiraf | B10: 13
A11: Pelipper | B11: 12
A12: Charizard_Mega_Y | B12: 11
A13: Torkoal | B13: 10
... A88: Dragonite Mega | B88: 1

Sheet Hoja3
A3: pokemon | B3: Cuenta de pokemon
A4: Aegislash blade | B4: 1
A5: Aerodactyl | B5: 10
A6: Aerodactyl Mega | B6: 3
A7: Arcanine | B7: 1
A8: Archaludon | B8: 4
A9: Ariados | B9: 1
A10: Basculegion-Male | B10: 27
A11: Blastoise | B11: 1
A12: Camerupt mega | B12: 1
A13: Charizard_Mega_Y | B13: 11
A14: Corviknight | B14: 2
A15: Dragonite | B15: 5
... A51: Whimsicott | B51: 2
A52: (empty)
A53: 0 | B53: 36
A54: kommo | B54: 4
A55: Total Result | B55: 264

Sheet dinamica
B1: pokemon
B2: =Resultados!J2 -> Aerodactyl
B3: =Resultados!J3 -> Arcanine
B4: =Resultados!J4 -> Kangaskhan Mega
B5: =Resultados!J5 -> Charizard_Mega_Y
B6: =Resultados!J6 -> 0
B7: =Resultados!J7 -> 0
B8: =Resultados!J8 -> Venusaur Mega
B9: =Resultados!J9 -> Aerodactyl Mega
B10: =Resultados!J10 -> Pelipper
B11: =Resultados!J11 -> Venusaur
B12: =Resultados!J12 -> Gardevoir Mega
B13: =Resultados!J13 -> Incineroar
... B45: =Resultados!J45 -> Charizard_Mega_Y
B46: =Resultados!K2 -> kommo
B47: =Resultados!K3 -> Gardevoir Mega
B48: =Resultados!K4 -> Farigiraf
B49: =Resultados!K5 -> Floette-Eternal
B50: =Resultados!K6 -> 0
B51: =Resultados!K7 -> 0
B52: =Resultados!K8 -> Archaludon
B53: =Resultados!K9 -> Scovillan mega
B54: =Resultados!K10 -> Basculegion-Male
B55: =Resultados!K11 -> Scizor
B56: =Resultados!K12 -> Garchomp
B57: =Resultados!K13 -> Farigiraf
... B89: =Resultados!K45 -> Aerodactyl
B90: =Resultados!L2 -> Kingambit
B91: =Resultados!L3 -> Tyranitar
B92: =Resultados!L4 -> Basculegion-Male
B93: =Resultados!L5 -> Aerodactyl
B94: =Resultados!L6 -> 0
B95: =Resultados!L7 -> 0
B96: =Resultados!L8 -> Pelipper
B97: =Resultados!L9 -> kommo
B98: =Resultados!L10 -> Dragonite
B99: =Resultados!L11 -> Pelipper
B100: =Resultados!L12 -> Talonflame
B101: =Resultados!L13 -> Charizard_Mega_Y
... B133: =Resultados!L45 -> Ariados
...
